..........
----------------------------------------------------------------------
Ran 10 tests in 0.001s

OK

======================================================================
FAIL: test_vectors (cpu.Test74181) (step=48, s=15, m=0, a=1, b=0, cin=1, result=16)
----------------------------------------------------------------------
Traceback (most recent call last):
  File "/home/PatrickDoyle/projects/cpu/cpu.py", line 538, in test_vectors
    self._check( result, a, b, s, m, cin )
  File "/home/PatrickDoyle/projects/cpu/cpu.py", line 542, in _check
    self.assertEqual( expected, result )
AssertionError: 16 != 1

----------------------------------------------------------------------
Ran 1 test in 0.019s

FAILED (failures=1)
